Workbook
Name ボタン2_Click: [1]!ボタン2_Click
Name ボタン2_Click: [1]!ボタン2_Click
Name ボタン2_Click: [1]!ボタン2_Click
Name ボタン2_Click: [1]!ボタン2_Click
Name ボタン2_Click: [1]!ボタン2_Click

Sheet IN
A1: {='Label FG'!F3:F3} -> 226 | B1: PT. TASM | E1: =$A$1 -> 226 | F1: PT. TASM | I1: =$A$1 -> 226 | J1: PT. TASM | M1: =$A$1 -> 226 | N1: PT. TASM
A2: Part No | B2: : | C2: =VLOOKUP(A1,'List Part'!$A$5:$C$374,2,0) -> 955985 | E2: Part No | F2: : | G2: =$C$2 -> 955985 | I2: Part No | J2: : | K2: =$C$2 -> 955985 | M2: Part No | N2: : | O2: =$C$2 -> 955985
A3: Part Name | B3: : | C3: =VLOOKUP(A1,'List Part'!$A$5:$C$374,3,0) -> DIN CONNECTOR FITTING | E3: Part Name | F3: : | G3: =$C$3 -> DIN CONNECTOR FITTING | I3: Part Name | J3: : | K3: =$C$3 -> DIN CONNECTOR FITTING | M3: Part Name | N3: : | O3: =$C$3 -> DIN CONNECTOR FITTING
A4: QTY | B4: : | C4: =VLOOKUP(A1,'List Part'!$A$5:$P$374,15,0) -> 200 | E4: QTY | F4: : | G4: =$C$4 -> 200 | I4: QTY | J4: : | K4: =$C$4 -> 200 | M4: QTY | N4: : | O4: =$C$4 -> 200
A5: Berat | B5: : | C5: gram | E5: Berat | F5: : | G5: gram | I5: Berat | J5: : | K5: gram | M5: Berat | N5: : | O5: gram
A6: Tgl prod | B6: : | C6: =VLOOKUP(A1,'List Part'!$A$5:$P$374,6,0) -> 0 | E6: Tgl prod | F6: : | G6: =$C$6 -> 0 | I6: Tgl prod | J6: : | K6: =$C$6 -> 0 | M6: Tgl prod | N6: : | O6: =$C$6 -> 0
A7: Checker | B7: : | C7: IN 06 04 | E7: Checker | F7: : | G7: =C7 -> IN 06 04 | I7: Checker | J7: : | K7: =G7 -> IN 06 04 | M7: Checker | N7: : | O7: =K7 -> IN 06 04
A9: =$A$1 -> 226 | B9: PT. TASM | E9: =$A$1 -> 226 | F9: PT. TASM | I9: =$A$1 -> 226 | J9: PT. TASM | M9: =$A$1 -> 226 | N9: PT. TASM
A10: Part No | B10: : | C10: =$C$2 -> 955985 | E10: Part No | F10: : | G10: =$C$2 -> 955985 | I10: Part No | J10: : | K10: =$C$2 -> 955985 | M10: Part No | N10: : | O10: =$C$2 -> 955985
A11: Part Name | B11: : | C11: =$C$3 -> DIN CONNECTOR FITTING | E11: Part Name | F11: : | G11: =$C$3 -> DIN CONNECTOR FITTING | I11: Part Name | J11: : | K11: =$C$3 -> DIN CONNECTOR FITTING | M11: Part Name | N11: : | O11: =$C$3 -> DIN CONNECTOR FITTING
A12: QTY | B12: : | C12: =$C$4 -> 200 | E12: QTY | F12: : | G12: =$C$4 -> 200 | I12: QTY | J12: : | K12: =$C$4 -> 200 | M12: QTY | N12: : | O12: =$C$4 -> 200
A13: Berat | B13: : | C13: gram | E13: Berat | F13: : | G13: gram | I13: Berat | J13: : | K13: gram | M13: Berat | N13: : | O13: gram
A14: Tgl prod | B14: : | C14: =$C$6 -> 0 | E14: Tgl prod | F14: : | G14: =$C$6 -> 0 | I14: Tgl prod | J14: : | K14: =$C$6 -> 0 | M14: Tgl prod | N14: : | O14: =$C$6 -> 0
A15: Checker | B15: : | C15: =C7 -> IN 06 04 | E15: Checker | F15: : | G15: =C15 -> IN 06 04 | I15: Checker | J15: : | K15: =G15 -> IN 06 04 | M15: Checker | N15: : | O15: =K15 -> IN 06 04
A17: =$A$1 -> 226 | B17: PT. TASM | E17: =$A$1 -> 226 | F17: PT. TASM | I17: =$A$1 -> 226 | J17: PT. TASM | M17: =$A$1 -> 226 | N17: PT. TASM
A18: Part No | B18: : | C18: =$C$2 -> 955985 | E18: Part No | F18: : | G18: =$C$2 -> 955985 | I18: Part No | J18: : | K18: =$C$2 -> 955985 | M18: Part No | N18: : | O18: =$C$2 -> 955985
A19: Part Name | B19: : | C19: =$C$3 -> DIN CONNECTOR FITTING | E19: Part Name | F19: : | G19: =$C$3 -> DIN CONNECTOR FITTING | I19: Part Name | J19: : | K19: =$C$3 -> DIN CONNECTOR FITTING | M19: Part Name | N19: : | O19: =$C$3 -> DIN CONNECTOR FITTING
A20: QTY | B20: : | C20: =$C$4 -> 200 | E20: QTY | F20: : | G20: =$C$4 -> 200 | I20: QTY | J20: : | K20: =$C$4 -> 200 | M20: QTY | N20: : | O20: =$C$4 -> 200
A21: Berat | B21: : | C21: gram | E21: Berat | F21: : | G21: gram | I21: Berat | J21: : | K21: gram | M21: Berat | N21: : | O21: gram
A22: Tgl prod | B22: : | C22: =$C$6 -> 0 | E22: Tgl prod | F22: : | G22: =$C$6 -> 0 | I22: Tgl prod | J22: : | K22: =$C$6 -> 0 | M22: Tgl prod | N22: : | O22: =$C$6 -> 0
A23: Checker | B23: : | C23: =C15 -> IN 06 04 | E23: Checker | F23: : | G23: =C23 -> IN 06 04 | I23: Checker | J23: : | K23: =G23 -> IN 06 04 | M23: Checker | N23: : | O23: =K23 -> IN 06 04
A25: =$A$1 -> 226 | B25: PT. TASM | E25: =$A$1 -> 226 | F25: PT. TASM | I25: =$A$1 -> 226 | J25: PT. TASM | M25: =$A$1 -> 226 | N25: PT. TASM
A26: Part No | B26: : | C26: =$C$2 -> 955985 | E26: Part No | F26: : | G26: =$C$2 -> 955985 | I26: Part No | J26: : | K26: =$C$2 -> 955985 | M26: Part No | N26: : | O26: =$C$2 -> 955985
A27: Part Name | B27: : | C27: =$C$3 -> DIN CONNECTOR FITTING | E27: Part Name | F27: : | G27: =$C$3 -> DIN CONNECTOR FITTING | I27: Part Name | J27: : | K27: =$C$3 -> DIN CONNECTOR FITTING | M27: Part Name | N27: : | O27: =$C$3 -> DIN CONNECTOR FITTING
A28: QTY | B28: : | C28: =$C$4 -> 200 | E28: QTY | F28: : | G28: =$C$4 -> 200 | I28: QTY | J28: : | K28: =$C$4 -> 200 | M28: QTY | N28: : | O28: =$C$4 -> 200
A29: Berat | B29: : | C29: gram | E29: Berat | F29: : | G29: gram | I29: Berat | J29: : | K29: gram | M29: Berat | N29: : | O29: gram
A30: Tgl prod | B30: : | C30: =$C$6 -> 0 | E30: Tgl prod | F30: : | G30: =$C$6 -> 0 | I30: Tgl prod | J30: : | K30: =$C$6 -> 0 | M30: Tgl prod | N30: : | O30: =$C$6 -> 0
A31: Checker | B31: : | C31: =C23 -> IN 06 04 | E31: Checker | F31: : | G31: =C31 -> IN 06 04 | I31: Checker | J31: : | K31: =G31 -> IN 06 04 | M31: Checker | N31: : | O31: =K31 -> IN 06 04
A33: =$A$1 -> 226 | B33: PT. TASM | E33: =$A$1 -> 226 | F33: PT. TASM | I33: =$A$1 -> 226 | J33: PT. TASM | M33: =$A$1 -> 226 | N33: PT. TASM
A34: Part No | B34: : | C34: =$C$2 -> 955985 | E34: Part No | F34: : | G34: =$C$2 -> 955985 | I34: Part No | J34: : | K34: =$C$2 -> 955985 | M34: Part No | N34: : | O34: =$C$2 -> 955985
A35: Part Name | B35: : | C35: =$C$3 -> DIN CONNECTOR FITTING | E35: Part Name | F35: : | G35: =$C$3 -> DIN CONNECTOR FITTING | I35: Part Name | J35: : | K35: =$C$3 -> DIN CONNECTOR FITTING | M35: Part Name | N35: : | O35: =$C$3 -> DIN CONNECTOR FITTING
A36: QTY | B36: : | C36: =$C$4 -> 200 | E36: QTY | F36: : | G36: =$C$4 -> 200 | I36: QTY | J36: : | K36: =$C$4 -> 200 | M36: QTY | N36: : | O36: =$C$4 -> 200
A37: Berat | B37: : | C37: gram | E37: Berat | F37: : | G37: gram | I37: Berat | J37: : | K37: gram | M37: Berat | N37: : | O37: gram
A38: Tgl prod | B38: : | C38: =$C$6 -> 0 | E38: Tgl prod | F38: : | G38: =$C$6 -> 0 | I38: Tgl prod | J38: : | K38: =$C$6 -> 0 | M38: Tgl prod | N38: : | O38: =$C$6 -> 0
A39: Checker | B39: : | C39: =C31 -> IN 06 04 | E39: Checker | F39: : | G39: =C39 -> IN 06 04 | I39: Checker | J39: : | K39: =G39 -> IN 06 04 | M39: Checker | N39: : | O39: =K39 -> IN 06 04
A41: =$A$1 -> 226 | B41: PT. TASM | E41: =$A$1 -> 226 | F41: PT. TASM | I41: =$A$1 -> 226 | J41: PT. TASM | M41: =$A$1 -> 226 | N41: PT. TASM
A42: Part No | B42: : | C42: =$C$2 -> 955985 | E42: Part No | F42: : | G42: =$C$2 -> 955985 | I42: Part No | J42: : | K42: =$C$2 -> 955985 | M42: Part No | N42: : | O42: =$C$2 -> 955985
A43: Part Name | B43: : | C43: =$C$3 -> DIN CONNECTOR FITTING | E43: Part Name | F43: : | G43: =$C$3 -> DIN CONNECTOR FITTING | I43: Part Name | J43: : | K43: =$C$3 -> DIN CONNECTOR FITTING | M43: Part Name | N43: : | O43: =$C$3 -> DIN CONNECTOR FITTING
A44: QTY | B44: : | C44: =$C$4 -> 200 | E44: QTY | F44: : | G44: =$C$4 -> 200 | I44: QTY | J44: : | K44: =$C$4 -> 200 | M44: QTY | N44: : | O44: =$C$4 -> 200
A45: Berat | B45: : | C45: gram | E45: Berat | F45: : | G45: gram | I45: Berat | J45: : | K45: gram | M45: Berat | N45: : | O45: gram
...

Sheet OK
A1: {='Label FG'!F3:F3} -> 226 | B1: PT. TASM | E1: =$A$1 -> 226 | F1: PT. TASM | I1: =$A$1 -> 226 | J1: PT. TASM | M1: =$A$1 -> 226 | N1: PT. TASM
A2: Part No | B2: : | C2: =VLOOKUP(A1,'List Part'!$A$5:$C$374,2,0) -> 955985 | E2: Part No | F2: : | G2: =$C$2 -> 955985 | I2: Part No | J2: : | K2: =$C$2 -> 955985 | M2: Part No | N2: : | O2: =$C$2 -> 955985
A3: Part Name | B3: : | C3: =VLOOKUP(A1,'List Part'!$A$5:$C$374,3,0) -> DIN CONNECTOR FITTING | E3: Part Name | F3: : | G3: =$C$3 -> DIN CONNECTOR FITTING | I3: Part Name | J3: : | K3: =$C$3 -> DIN CONNECTOR FITTING | M3: Part Name | N3: : | O3: =$C$3 -> DIN CONNECTOR FITTING
A4: QTY | B4: : | C4: =VLOOKUP(A1,'List Part'!$A$5:$P$374,15,0) -> 200 | E4: QTY | F4: : | G4: =$C$4 -> 200 | I4: QTY | J4: : | K4: =$C$4 -> 200 | M4: QTY | N4: : | O4: =$C$4 -> 200
A5: Berat | B5: : | C5: gram | E5: Berat | F5: : | G5: gram | I5: Berat | J5: : | K5: gram | M5: Berat | N5: : | O5: gram
A6: Tgl prod | B6: : | C6: =VLOOKUP(A1,'List Part'!$A$5:$P$374,6,0) -> 0 | E6: Tgl prod | F6: : | G6: =$C$6 -> 0 | I6: Tgl prod | J6: : | K6: =$C$6 -> 0 | M6: Tgl prod | N6: : | O6: =$C$6 -> 0
A7: Checker | B7: : | C7: OK 01 03 | E7: Checker | F7: : | G7: =C7 -> OK 01 03 | I7: Checker | J7: : | K7: =G7 -> OK 01 03 | M7: Checker | N7: : | O7: =K7 -> OK 01 03
A9: =$A$1 -> 226 | B9: PT. TASM | E9: =$A$1 -> 226 | F9: PT. TASM | I9: =$A$1 -> 226 | J9: PT. TASM | M9: =$A$1 -> 226 | N9: PT. TASM
A10: Part No | B10: : | C10: =$C$2 -> 955985 | E10: Part No | F10: : | G10: =$C$2 -> 955985 | I10: Part No | J10: : | K10: =$C$2 -> 955985 | M10: Part No | N10: : | O10: =$C$2 -> 955985
A11: Part Name | B11: : | C11: =$C$3 -> DIN CONNECTOR FITTING | E11: Part Name | F11: : | G11: =$C$3 -> DIN CONNECTOR FITTING | I11: Part Name | J11: : | K11: =$C$3 -> DIN CONNECTOR FITTING | M11: Part Name | N11: : | O11: =$C$3 -> DIN CONNECTOR FITTING
A12: QTY | B12: : | C12: =$C$4 -> 200 | E12: QTY | F12: : | G12: =$C$4 -> 200 | I12: QTY | J12: : | K12: =$C$4 -> 200 | M12: QTY | N12: : | O12: =$C$4 -> 200
A13: Berat | B13: : | C13: gram | E13: Berat | F13: : | G13: gram | I13: Berat | J13: : | K13: gram | M13: Berat | N13: : | O13: gram
A14: Tgl prod | B14: : | C14: =$C$6 -> 0 | E14: Tgl prod | F14: : | G14: =$C$6 -> 0 | I14: Tgl prod | J14: : | K14: =$C$6 -> 0 | M14: Tgl prod | N14: : | O14: =$C$6 -> 0
A15: Checker | B15: : | C15: =C7 -> OK 01 03 | E15: Checker | F15: : | G15: =C15 -> OK 01 03 | I15: Checker | J15: : | K15: =G15 -> OK 01 03 | M15: Checker | N15: : | O15: =K15 -> OK 01 03
A17: =$A$1 -> 226 | B17: PT. TASM | E17: =$A$1 -> 226 | F17: PT. TASM | I17: =$A$1 -> 226 | J17: PT. TASM | M17: =$A$1 -> 226 | N17: PT. TASM
A18: Part No | B18: : | C18: =$C$2 -> 955985 | E18: Part No | F18: : | G18: =$C$2 -> 955985 | I18: Part No | J18: : | K18: =$C$2 -> 955985 | M18: Part No | N18: : | O18: =$C$2 -> 955985
A19: Part Name | B19: : | C19: =$C$3 -> DIN CONNECTOR FITTING | E19: Part Name | F19: : | G19: =$C$3 -> DIN CONNECTOR FITTING | I19: Part Name | J19: : | K19: =$C$3 -> DIN CONNECTOR FITTING | M19: Part Name | N19: : | O19: =$C$3 -> DIN CONNECTOR FITTING
A20: QTY | B20: : | C20: =$C$4 -> 200 | E20: QTY | F20: : | G20: =$C$4 -> 200 | I20: QTY | J20: : | K20: =$C$4 -> 200 | M20: QTY | N20: : | O20: =$C$4 -> 200
A21: Berat | B21: : | C21: gram | E21: Berat | F21: : | G21: gram | I21: Berat | J21: : | K21: gram | M21: Berat | N21: : | O21: gram
A22: Tgl prod | B22: : | C22: =$C$6 -> 0 | E22: Tgl prod | F22: : | G22: =$C$6 -> 0 | I22: Tgl prod | J22: : | K22: =$C$6 -> 0 | M22: Tgl prod | N22: : | O22: =$C$6 -> 0
A23: Checker | B23: : | C23: =C15 -> OK 01 03 | E23: Checker | F23: : | G23: =C23 -> OK 01 03 | I23: Checker | J23: : | K23: =G23 -> OK 01 03 | M23: Checker | N23: : | O23: =K23 -> OK 01 03
A25: =$A$1 -> 226 | B25: PT. TASM | E25: =$A$1 -> 226 | F25: PT. TASM | I25: =$A$1 -> 226 | J25: PT. TASM | M25: =$A$1 -> 226 | N25: PT. TASM
A26: Part No | B26: : | C26: =$C$2 -> 955985 | E26: Part No | F26: : | G26: =$C$2 -> 955985 | I26: Part No | J26: : | K26: =$C$2 -> 955985 | M26: Part No | N26: : | O26: =$C$2 -> 955985
A27: Part Name | B27: : | C27: =$C$3 -> DIN CONNECTOR FITTING | E27: Part Name | F27: : | G27: =$C$3 -> DIN CONNECTOR FITTING | I27: Part Name | J27: : | K27: =$C$3 -> DIN CONNECTOR FITTING | M27: Part Name | N27: : | O27: =$C$3 -> DIN CONNECTOR FITTING
A28: QTY | B28: : | C28: =$C$4 -> 200 | E28: QTY | F28: : | G28: =$C$4 -> 200 | I28: QTY | J28: : | K28: =$C$4 -> 200 | M28: QTY | N28: : | O28: =$C$4 -> 200
A29: Berat | B29: : | C29: gram | E29: Berat | F29: : | G29: gram | I29: Berat | J29: : | K29: gram | M29: Berat | N29: : | O29: gram
A30: Tgl prod | B30: : | C30: =$C$6 -> 0 | E30: Tgl prod | F30: : | G30: =$C$6 -> 0 | I30: Tgl prod | J30: : | K30: =$C$6 -> 0 | M30: Tgl prod | N30: : | O30: =$C$6 -> 0
A31: Checker | B31: : | C31: =C23 -> OK 01 03 | E31: Checker | F31: : | G31: =C31 -> OK 01 03 | I31: Checker | J31: : | K31: =G31 -> OK 01 03 | M31: Checker | N31: : | O31: =K31 -> OK 01 03
A33: =$A$1 -> 226 | B33: PT. TASM | E33: =$A$1 -> 226 | F33: PT. TASM | I33: =$A$1 -> 226 | J33: PT. TASM | M33: =$A$1 -> 226 | N33: PT. TASM
A34: Part No | B34: : | C34: =$C$2 -> 955985 | E34: Part No | F34: : | G34: =$C$2 -> 955985 | I34: Part No | J34: : | K34: =$C$2 -> 955985 | M34: Part No | N34: : | O34: =$C$2 -> 955985
A35: Part Name | B35: : | C35: =$C$3 -> DIN CONNECTOR FITTING | E35: Part Name | F35: : | G35: =$C$3 -> DIN CONNECTOR FITTING | I35: Part Name | J35: : | K35: =$C$3 -> DIN CONNECTOR FITTING | M35: Part Name | N35: : | O35: =$C$3 -> DIN CONNECTOR FITTING
A36: QTY | B36: : | C36: =$C$4 -> 200 | E36: QTY | F36: : | G36: =$C$4 -> 200 | I36: QTY | J36: : | K36: =$C$4 -> 200 | M36: QTY | N36: : | O36: =$C$4 -> 200
A37: Berat | B37: : | C37: gram | E37: Berat | F37: : | G37: gram | I37: Berat | J37: : | K37: gram | M37: Berat | N37: : | O37: gram
A38: Tgl prod | B38: : | C38: =$C$6 -> 0 | E38: Tgl prod | F38: : | G38: =$C$6 -> 0 | I38: Tgl prod | J38: : | K38: =$C$6 -> 0 | M38: Tgl prod | N38: : | O38: =$C$6 -> 0
A39: Checker | B39: : | C39: =C31 -> OK 01 03 | E39: Checker | F39: : | G39: =C39 -> OK 01 03 | I39: Checker | J39: : | K39: =G39 -> OK 01 03 | M39: Checker | N39: : | O39: =K39 -> OK 01 03
A41: =$A$1 -> 226 | B41: PT. TASM | E41: =$A$1 -> 226 | F41: PT. TASM | I41: =$A$1 -> 226 | J41: PT. TASM | M41: =$A$1 -> 226 | N41: PT. TASM
A42: Part No | B42: : | C42: =$C$2 -> 955985 | E42: Part No | F42: : | G42: =$C$2 -> 955985 | I42: Part No | J42: : | K42: =$C$2 -> 955985 | M42: Part No | N42: : | O42: =$C$2 -> 955985
A43: Part Name | B43: : | C43: =$C$3 -> DIN CONNECTOR FITTING | E43: Part Name | F43: : | G43: =$C$3 -> DIN CONNECTOR FITTING | I43: Part Name | J43: : | K43: =$C$3 -> DIN CONNECTOR FITTING | M43: Part Name | N43: : | O43: =$C$3 -> DIN CONNECTOR FITTING
A44: QTY | B44: : | C44: =$C$4 -> 200 | E44: QTY | F44: : | G44: =$C$4 -> 200 | I44: QTY | J44: : | K44: =$C$4 -> 200 | M44: QTY | N44: : | O44: =$C$4 -> 200
A45: Berat | B45: : | C45: gram | E45: Berat | F45: : | G45: gram | I45: Berat | J45: : | K45: gram | M45: Berat | N45: : | O45: gram
...

Sheet BY
A1: {='Label FG'!F3:F3} -> 226 | B1: PT. TASM | E1: =$A$1 -> 226 | F1: PT. TASM | I1: =$A$1 -> 226 | J1: PT. TASM | M1: =$A$1 -> 226 | N1: PT. TASM
A2: Part No | B2: : | C2: =VLOOKUP(A1,'List Part'!$A$5:$C$374,2,0) -> 955985 | E2: Part No | F2: : | G2: =$C$2 -> 955985 | I2: Part No | J2: : | K2: =$C$2 -> 955985 | M2: Part No | N2: : | O2: =$C$2 -> 955985
A3: Part Name | B3: : | C3: =VLOOKUP(A1,'List Part'!$A$5:$C$374,3,0) -> DIN CONNECTOR FITTING | E3: Part Name | F3: : | G3: =$C$3 -> DIN CONNECTOR FITTING | I3: Part Name | J3: : | K3: =$C$3 -> DIN CONNECTOR FITTING | M3: Part Name | N3: : | O3: =$C$3 -> DIN CONNECTOR FITTING
A4: QTY | B4: : | C4: =VLOOKUP(A1,'List Part'!$A$5:$P$374,15,0) -> 200 | E4: QTY | F4: : | G4: =$C$4 -> 200 | I4: QTY | J4: : | K4: =$C$4 -> 200 | M4: QTY | N4: : | O4: =$C$4 -> 200
A5: Berat | B5: : | C5: gram | E5: Berat | F5: : | G5: gram | I5: Berat | J5: : | K5: gram | M5: Berat | N5: : | O5: gram
A6: Tgl prod | B6: : | C6: =VLOOKUP(A1,'List Part'!$A$5:$P$374,6,0) -> 0 | E6: Tgl prod | F6: : | G6: =$C$6 -> 0 | I6: Tgl prod | J6: : | K6: =$C$6 -> 0 | M6: Tgl prod | N6: : | O6: =$C$6 -> 0
A7: Checker | B7: : | C7: BY 02 05 | E7: Checker | F7: : | G7: =C7 -> BY 02 05 | I7: Checker | J7: : | K7: =G7 -> BY 02 05 | M7: Checker | N7: : | O7: =K7 -> BY 02 05
A9: =$A$1 -> 226 | B9: PT. TASM | E9: =$A$1 -> 226 | F9: PT. TASM | I9: =$A$1 -> 226 | J9: PT. TASM | M9: =$A$1 -> 226 | N9: PT. TASM
A10: Part No | B10: : | C10: =$C$2 -> 955985 | E10: Part No | F10: : | G10: =$C$2 -> 955985 | I10: Part No | J10: : | K10: =$C$2 -> 955985 | M10: Part No | N10: : | O10: =$C$2 -> 955985
A11: Part Name | B11: : | C11: =$C$3 -> DIN CONNECTOR FITTING | E11: Part Name | F11: : | G11: =$C$3 -> DIN CONNECTOR FITTING | I11: Part Name | J11: : | K11: =$C$3 -> DIN CONNECTOR FITTING | M11: Part Name | N11: : | O11: =$C$3 -> DIN CONNECTOR FITTING
A12: QTY | B12: : | C12: =$C$4 -> 200 | E12: QTY | F12: : | G12: =$C$4 -> 200 | I12: QTY | J12: : | K12: =$C$4 -> 200 | M12: QTY | N12: : | O12: =$C$4 -> 200
A13: Berat | B13: : | C13: gram | E13: Berat | F13: : | G13: gram | I13: Berat | J13: : | K13: gram | M13: Berat | N13: : | O13: gram
A14: Tgl prod | B14: : | C14: =$C$6 -> 0 | E14: Tgl prod | F14: : | G14: =$C$6 -> 0 | I14: Tgl prod | J14: : | K14: =$C$6 -> 0 | M14: Tgl prod | N14: : | O14: =$C$6 -> 0
A15: Checker | B15: : | C15: =C7 -> BY 02 05 | E15: Checker | F15: : | G15: =C15 -> BY 02 05 | I15: Checker | J15: : | K15: =G15 -> BY 02 05 | M15: Checker | N15: : | O15: =K15 -> BY 02 05
A17: =$A$1 -> 226 | B17: PT. TASM | E17: =$A$1 -> 226 | F17: PT. TASM | I17: =$A$1 -> 226 | J17: PT. TASM | M17: =$A$1 -> 226 | N17: PT. TASM
A18: Part No | B18: : | C18: =$C$2 -> 955985 | E18: Part No | F18: : | G18: =$C$2 -> 955985 | I18: Part No | J18: : | K18: =$C$2 -> 955985 | M18: Part No | N18: : | O18: =$C$2 -> 955985
A19: Part Name | B19: : | C19: =$C$3 -> DIN CONNECTOR FITTING | E19: Part Name | F19: : | G19: =$C$3 -> DIN CONNECTOR FITTING | I19: Part Name | J19: : | K19: =$C$3 -> DIN CONNECTOR FITTING | M19: Part Name | N19: : | O19: =$C$3 -> DIN CONNECTOR FITTING
A20: QTY | B20: : | C20: =$C$4 -> 200 | E20: QTY | F20: : | G20: =$C$4 -> 200 | I20: QTY | J20: : | K20: =$C$4 -> 200 | M20: QTY | N20: : | O20: =$C$4 -> 200
A21: Berat | B21: : | C21: gram | E21: Berat | F21: : | G21: gram | I21: Berat | J21: : | K21: gram | M21: Berat | N21: : | O21: gram
A22: Tgl prod | B22: : | C22: =$C$6 -> 0 | E22: Tgl prod | F22: : | G22: =$C$6 -> 0 | I22: Tgl prod | J22: : | K22: =$C$6 -> 0 | M22: Tgl prod | N22: : | O22: =$C$6 -> 0
A23: Checker | B23: : | C23: =C15 -> BY 02 05 | E23: Checker | F23: : | G23: =C23 -> BY 02 05 | I23: Checker | J23: : | K23: =G23 -> BY 02 05 | M23: Checker | N23: : | O23: =K23 -> BY 02 05
A25: =$A$1 -> 226 | B25: PT. TASM | E25: =$A$1 -> 226 | F25: PT. TASM | I25: =$A$1 -> 226 | J25: PT. TASM | M25: =$A$1 -> 226 | N25: PT. TASM
A26: Part No | B26: : | C26: =$C$2 -> 955985 | E26: Part No | F26: : | G26: =$C$2 -> 955985 | I26: Part No | J26: : | K26: =$C$2 -> 955985 | M26: Part No | N26: : | O26: =$C$2 -> 955985
A27: Part Name | B27: : | C27: =$C$3 -> DIN CONNECTOR FITTING | E27: Part Name | F27: : | G27: =$C$3 -> DIN CONNECTOR FITTING | I27: Part Name | J27: : | K27: =$C$3 -> DIN CONNECTOR FITTING | M27: Part Name | N27: : | O27: =$C$3 -> DIN CONNECTOR FITTING
A28: QTY | B28: : | C28: =$C$4 -> 200 | E28: QTY | F28: : | G28: =$C$4 -> 200 | I28: QTY | J28: : | K28: =$C$4 -> 200 | M28: QTY | N28: : | O28: =$C$4 -> 200
A29: Berat | B29: : | C29: gram | E29: Berat | F29: : | G29: gram | I29: Berat | J29: : | K29: gram | M29: Berat | N29: : | O29: gram
A30: Tgl prod | B30: : | C30: =$C$6 -> 0 | E30: Tgl prod | F30: : | G30: =$C$6 -> 0 | I30: Tgl prod | J30: : | K30: =$C$6 -> 0 | M30: Tgl prod | N30: : | O30: =$C$6 -> 0
A31: Checker | B31: : | C31: =C23 -> BY 02 05 | E31: Checker | F31: : | G31: =C31 -> BY 02 05 | I31: Checker | J31: : | K31: =G31 -> BY 02 05 | M31: Checker | N31: : | O31: =K31 -> BY 02 05
A33: =$A$1 -> 226 | B33: PT. TASM | E33: =$A$1 -> 226 | F33: PT. TASM | I33: =$A$1 -> 226 | J33: PT. TASM | M33: =$A$1 -> 226 | N33: PT. TASM
A34: Part No | B34: : | C34: =$C$2 -> 955985 | E34: Part No | F34: : | G34: =$C$2 -> 955985 | I34: Part No | J34: : | K34: =$C$2 -> 955985 | M34: Part No | N34: : | O34: =$C$2 -> 955985
A35: Part Name | B35: : | C35: =$C$3 -> DIN CONNECTOR FITTING | E35: Part Name | F35: : | G35: =$C$3 -> DIN CONNECTOR FITTING | I35: Part Name | J35: : | K35: =$C$3 -> DIN CONNECTOR FITTING | M35: Part Name | N35: : | O35: =$C$3 -> DIN CONNECTOR FITTING
A36: QTY | B36: : | C36: =$C$4 -> 200 | E36: QTY | F36: : | G36: =$C$4 -> 200 | I36: QTY | J36: : | K36: =$C$4 -> 200 | M36: QTY | N36: : | O36: =$C$4 -> 200
A37: Berat | B37: : | C37: gram | E37: Berat | F37: : | G37: gram | I37: Berat | J37: : | K37: gram | M37: Berat | N37: : | O37: gram
A38: Tgl prod | B38: : | C38: =$C$6 -> 0 | E38: Tgl prod | F38: : | G38: =$C$6 -> 0 | I38: Tgl prod | J38: : | K38: =$C$6 -> 0 | M38: Tgl prod | N38: : | O38: =$C$6 -> 0
A39: Checker | B39: : | C39: =C31 -> BY 02 05 | E39: Checker | F39: : | G39: =C39 -> BY 02 05 | I39: Checker | J39: : | K39: =G39 -> BY 02 05 | M39: Checker | N39: : | O39: =K39 -> BY 02 05
A41: =$A$1 -> 226 | B41: PT. TASM | E41: =$A$1 -> 226 | F41: PT. TASM | I41: =$A$1 -> 226 | J41: PT. TASM | M41: =$A$1 -> 226 | N41: PT. TASM
A42: Part No | B42: : | C42: =$C$2 -> 955985 | E42: Part No | F42: : | G42: =$C$2 -> 955985 | I42: Part No | J42: : | K42: =$C$2 -> 955985 | M42: Part No | N42: : | O42: =$C$2 -> 955985
A43: Part Name | B43: : | C43: =$C$3 -> DIN CONNECTOR FITTING | E43: Part Name | F43: : | G43: =$C$3 -> DIN CONNECTOR FITTING | I43: Part Name | J43: : | K43: =$C$3 -> DIN CONNECTOR FITTING | M43: Part Name | N43: : | O43: =$C$3 -> DIN CONNECTOR FITTING
A44: QTY | B44: : | C44: =$C$4 -> 200 | E44: QTY | F44: : | G44: =$C$4 -> 200 | I44: QTY | J44: : | K44: =$C$4 -> 200 | M44: QTY | N44: : | O44: =$C$4 -> 200
A45: Berat | B45: : | C45: gram | E45: Berat | F45: : | G45: gram | I45: Berat | J45: : | K45: gram | M45: Berat | N45: : | O45: gram
...

Sheet SPY
A1: {='Label FG'!F3:F3} -> 226 | B1: PT. TASM | E1: =$A$1 -> 226 | F1: PT. TASM | I1: =$A$1 -> 226 | J1: PT. TASM | M1: =$A$1 -> 226 | N1: PT. TASM
A2: Part No | B2: : | C2: =VLOOKUP(A1,'List Part'!$A$5:$C$374,2,0) -> 955985 | E2: Part No | F2: : | G2: =$C$2 -> 955985 | I2: Part No | J2: : | K2: =$C$2 -> 955985 | M2: Part No | N2: : | O2: =$C$2 -> 955985
A3: Part Name | B3: : | C3: =VLOOKUP(A1,'List Part'!$A$5:$C$374,3,0) -> DIN CONNECTOR FITTING | E3: Part Name | F3: : | G3: =$C$3 -> DIN CONNECTOR FITTING | I3: Part Name | J3: : | K3: =$C$3 -> DIN CONNECTOR FITTING | M3: Part Name | N3: : | O3: =$C$3 -> DIN CONNECTOR FITTING
A4: QTY | B4: : | C4: =VLOOKUP(A1,'List Part'!$A$5:$P$374,15,0) -> 200 | E4: QTY | F4: : | G4: =$C$4 -> 200 | I4: QTY | J4: : | K4: =$C$4 -> 200 | M4: QTY | N4: : | O4: =$C$4 -> 200
A5: Berat | B5: : | C5: gram | E5: Berat | F5: : | G5: gram | I5: Berat | J5: : | K5: gram | M5: Berat | N5: : | O5: gram
A6: Tgl prod | B6: : | C6: =VLOOKUP(A1,'List Part'!$A$5:$P$374,6,0) -> 0 | E6: Tgl prod | F6: : | G6: =$C$6 -> 0 | I6: Tgl prod | J6: : | K6: =$C$6 -> 0 | M6: Tgl prod | N6: : | O6: =$C$6 -> 0
A7: Checker | B7: : | C7: A | E7: Checker | F7: : | G7: =C7 -> A | I7: Checker | J7: : | K7: =G7 -> A | M7: Checker | N7: : | O7: =K7 -> A
A9: =$A$1 -> 226 | B9: PT. TASM | E9: =$A$1 -> 226 | F9: PT. TASM | I9: =$A$1 -> 226 | J9: PT. TASM | M9: =$A$1 -> 226 | N9: PT. TASM
A10: Part No | B10: : | C10: =$C$2 -> 955985 | E10: Part No | F10: : | G10: =$C$2 -> 955985 | I10: Part No | J10: : | K10: =$C$2 -> 955985 | M10: Part No | N10: : | O10: =$C$2 -> 955985
A11: Part Name | B11: : | C11: =$C$3 -> DIN CONNECTOR FITTING | E11: Part Name | F11: : | G11: =$C$3 -> DIN CONNECTOR FITTING | I11: Part Name | J11: : | K11: =$C$3 -> DIN CONNECTOR FITTING | M11: Part Name | N11: : | O11: =$C$3 -> DIN CONNECTOR FITTING
A12: QTY | B12: : | C12: =$C$4 -> 200 | E12: QTY | F12: : | G12: =$C$4 -> 200 | I12: QTY | J12: : | K12: =$C$4 -> 200 | M12: QTY | N12: : | O12: =$C$4 -> 200
A13: Berat | B13: : | C13: gram | E13: Berat | F13: : | G13: gram | I13: Berat | J13: : | K13: gram | M13: Berat | N13: : | O13: gram
A14: Tgl prod | B14: : | C14: =$C$6 -> 0 | E14: Tgl prod | F14: : | G14: =$C$6 -> 0 | I14: Tgl prod | J14: : | K14: =$C$6 -> 0 | M14: Tgl prod | N14: : | O14: =$C$6 -> 0
A15: Checker | B15: : | C15: =C7 -> A | E15: Checker | F15: : | G15: =C15 -> A | I15: Checker | J15: : | K15: =G15 -> A | M15: Checker | N15: : | O15: =K15 -> A
A17: =$A$1 -> 226 | B17: PT. TASM | E17: =$A$1 -> 226 | F17: PT. TASM | I17: =$A$1 -> 226 | J17: PT. TASM | M17: =$A$1 -> 226 | N17: PT. TASM
A18: Part No | B18: : | C18: =$C$2 -> 955985 | E18: Part No | F18: : | G18: =$C$2 -> 955985 | I18: Part No | J18: : | K18: =$C$2 -> 955985 | M18: Part No | N18: : | O18: =$C$2 -> 955985
A19: Part Name | B19: : | C19: =$C$3 -> DIN CONNECTOR FITTING | E19: Part Name | F19: : | G19: =$C$3 -> DIN CONNECTOR FITTING | I19: Part Name | J19: : | K19: =$C$3 -> DIN CONNECTOR FITTING | M19: Part Name | N19: : | O19: =$C$3 -> DIN CONNECTOR FITTING
A20: QTY | B20: : | C20: =$C$4 -> 200 | E20: QTY | F20: : | G20: =$C$4 -> 200 | I20: QTY | J20: : | K20: =$C$4 -> 200 | M20: QTY | N20: : | O20: =$C$4 -> 200
A21: Berat | B21: : | C21: gram | E21: Berat | F21: : | G21: gram | I21: Berat | J21: : | K21: gram | M21: Berat | N21: : | O21: gram
A22: Tgl prod | B22: : | C22: =$C$6 -> 0 | E22: Tgl prod | F22: : | G22: =$C$6 -> 0 | I22: Tgl prod | J22: : | K22: =$C$6 -> 0 | M22: Tgl prod | N22: : | O22: =$C$6 -> 0
A23: Checker | B23: : | C23: =C15 -> A | E23: Checker | F23: : | G23: =C23 -> A | I23: Checker | J23: : | K23: =G23 -> A | M23: Checker | N23: : | O23: =K23 -> A
A25: =$A$1 -> 226 | B25: PT. TASM | E25: =$A$1 -> 226 | F25: PT. TASM | I25: =$A$1 -> 226 | J25: PT. TASM | M25: =$A$1 -> 226 | N25: PT. TASM
A26: Part No | B26: : | C26: =$C$2 -> 955985 | E26: Part No | F26: : | G26: =$C$2 -> 955985 | I26: Part No | J26: : | K26: =$C$2 -> 955985 | M26: Part No | N26: : | O26: =$C$2 -> 955985
A27: Part Name | B27: : | C27: =$C$3 -> DIN CONNECTOR FITTING | E27: Part Name | F27: : | G27: =$C$3 -> DIN CONNECTOR FITTING | I27: Part Name | J27: : | K27: =$C$3 -> DIN CONNECTOR FITTING | M27: Part Name | N27: : | O27: =$C$3 -> DIN CONNECTOR FITTING
A28: QTY | B28: : | C28: =$C$4 -> 200 | E28: QTY | F28: : | G28: =$C$4 -> 200 | I28: QTY | J28: : | K28: =$C$4 -> 200 | M28: QTY | N28: : | O28: =$C$4 -> 200
A29: Berat | B29: : | C29: gram | E29: Berat | F29: : | G29: gram | I29: Berat | J29: : | K29: gram | M29: Berat | N29: : | O29: gram
A30: Tgl prod | B30: : | C30: =$C$6 -> 0 | E30: Tgl prod | F30: : | G30: =$C$6 -> 0 | I30: Tgl prod | J30: : | K30: =$C$6 -> 0 | M30: Tgl prod | N30: : | O30: =$C$6 -> 0
A31: Checker | B31: : | C31: =C23 -> A | E31: Checker | F31: : | G31: =C31 -> A | I31: Checker | J31: : | K31: =G31 -> A | M31: Checker | N31: : | O31: =K31 -> A
A33: =$A$1 -> 226 | B33: PT. TASM | E33: =$A$1 -> 226 | F33: PT. TASM | I33: =$A$1 -> 226 | J33: PT. TASM | M33: =$A$1 -> 226 | N33: PT. TASM
A34: Part No | B34: : | C34: =$C$2 -> 955985 | E34: Part No | F34: : | G34: =$C$2 -> 955985 | I34: Part No | J34: : | K34: =$C$2 -> 955985 | M34: Part No | N34: : | O34: =$C$2 -> 955985
A35: Part Name | B35: : | C35: =$C$3 -> DIN CONNECTOR FITTING | E35: Part Name | F35: : | G35: =$C$3 -> DIN CONNECTOR FITTING | I35: Part Name | J35: : | K35: =$C$3 -> DIN CONNECTOR FITTING | M35: Part Name | N35: : | O35: =$C$3 -> DIN CONNECTOR FITTING
A36: QTY | B36: : | C36: =$C$4 -> 200 | E36: QTY | F36: : | G36: =$C$4 -> 200 | I36: QTY | J36: : | K36: =$C$4 -> 200 | M36: QTY | N36: : | O36: =$C$4 -> 200
A37: Berat | B37: : | C37: gram | E37: Berat | F37: : | G37: gram | I37: Berat | J37: : | K37: gram | M37: Berat | N37: : | O37: gram
A38: Tgl prod | B38: : | C38: =$C$6 -> 0 | E38: Tgl prod | F38: : | G38: =$C$6 -> 0 | I38: Tgl prod | J38: : | K38: =$C$6 -> 0 | M38: Tgl prod | N38: : | O38: =$C$6 -> 0
A39: Checker | B39: : | C39: =C31 -> A | E39: Checker | F39: : | G39: =C39 -> A | I39: Checker | J39: : | K39: =G39 -> A | M39: Checker | N39: : | O39: =K39 -> A
A41: =$A$1 -> 226 | B41: PT. TASM | E41: =$A$1 -> 226 | F41: PT. TASM | I41: =$A$1 -> 226 | J41: PT. TASM | M41: =$A$1 -> 226 | N41: PT. TASM
A42: Part No | B42: : | C42: =$C$2 -> 955985 | E42: Part No | F42: : | G42: =$C$2 -> 955985 | I42: Part No | J42: : | K42: =$C$2 -> 955985 | M42: Part No | N42: : | O42: =$C$2 -> 955985
A43: Part Name | B43: : | C43: =$C$3 -> DIN CONNECTOR FITTING | E43: Part Name | F43: : | G43: =$C$3 -> DIN CONNECTOR FITTING | I43: Part Name | J43: : | K43: =$C$3 -> DIN CONNECTOR FITTING | M43: Part Name | N43: : | O43: =$C$3 -> DIN CONNECTOR FITTING
A44: QTY | B44: : | C44: =$C$4 -> 200 | E44: QTY | F44: : | G44: =$C$4 -> 200 | I44: QTY | J44: : | K44: =$C$4 -> 200 | M44: QTY | N44: : | O44: =$C$4 -> 200
A45: Berat | B45: : | C45: gram | E45: Berat | F45: : | G45: gram | I45: Berat | J45: : | K45: gram | M45: Berat | N45: : | O45: gram
...

Sheet Label FG
B1: PT. TEKUN ASAS SUMBER MAKMUR | I1: PT. TEKUN ASAS SUMBER MAKMUR
A2: Customer name | B2: : | C2: =VLOOKUP(F3,'List Part'!$A$5:$D$426,4,0) -> PT. KAWAI INDONESIA | F2: Code : | H2: Customer name | I2: : | J2: =$C$2 -> PT. KAWAI INDONESIA | M2: Code :
A3: Part no | B3: : | C3: =VLOOKUP(F3,'List Part'!$A$5:$C$426,2,0) -> 955985 | F3: 226 | H3: Part no | I3: : | J3: =$C$3 -> 955985 | M3: =$F$3 -> 226
A4: Part name | B4: : | C4: =VLOOKUP(F3,'List Part'!$A$5:$C$426,3,0) -> DIN CONNECTOR FITTING | H4: Part name | I4: : | J4: =$C$4 -> DIN CONNECTOR FITTING
A5: Model | B5: : | C5: =VLOOKUP($F$3,'List Part'!$A$5:$H$426,8,0) -> F28235 | H5: Model | I5: : | J5: =$C$5 -> F28235
A6: Delivery date | B6: : | F6: QR code | H6: Delivery date | I6: : | M6: QR code
A7: Berat per pack | B7: : | D7: Kg | H7: Berat per pack | I7: : | K7: Kg
A8: Quantity | B8: : | C8: =VLOOKUP(F3,'List Part'!$A$5:$E$426,5,0) -> 1000 | D8: Pcs | H8: Quantity | I8: : | J8: =$C$8 -> 1000 | K8: Pcs
A9: Inspector name | B9: : | H9: Inspector name | I9: :
A10: Prod. date | C10: Exp. date | E10: Status part | F10: OK | H10: Prod. date | J10: Exp. date | L10: Status part | M10: OK
A11: =VLOOKUP(F3,'List Part'!$A$5:$G$426,6,0) -> 0 | C11: =VLOOKUP(F3,'List Part'!$A$5:$G$426,7,0) -> 91 | H11: =$A$11 -> 0 | J11: =$C$11 -> 91
A12: F-QC-038. Date/Rev : 22.04.24/01 | H12: F-QC-038. Date/Rev : 22.04.24/01
B14: PT. TEKUN ASAS SUMBER MAKMUR | I14: PT. TEKUN ASAS SUMBER MAKMUR
A15: Customer name | B15: : | C15: =$C$2 -> PT. KAWAI INDONESIA | F15: Code : | H15: Customer name | I15: : | J15: =$C$2 -> PT. KAWAI INDONESIA | M15: Code :
A16: Part no | B16: : | C16: =$C$3 -> 955985 | F16: =$F$3 -> 226 | H16: Part no | I16: : | J16: =$C$3 -> 955985 | M16: =$F$3 -> 226
A17: Part name | B17: : | C17: =$C$4 -> DIN CONNECTOR FITTING | H17: Part name | I17: : | J17: =$C$4 -> DIN CONNECTOR FITTING
A18: Model | B18: : | C18: =$C$5 -> F28235 | H18: Model | I18: : | J18: =$C$5 -> F28235
A19: Delivery date | B19: : | F19: QR code | H19: Delivery date | I19: : | M19: QR code
A20: Berat per pack | B20: : | D20: Kg | H20: Berat per pack | I20: : | K20: Kg
A21: Quantity | B21: : | C21: =$C$8 -> 1000 | D21: Pcs | H21: Quantity | I21: : | J21: =$C$8 -> 1000 | K21: Pcs
A22: Inspector name | B22: : | H22: Inspector name | I22: :
A23: Prod. date | C23: Exp. date | E23: Status part | F23: OK | H23: Prod. date | J23: Exp. date | L23: Status part | M23: OK
A24: =$A$11 -> 0 | C24: =$C$11 -> 91 | H24: =$A$11 -> 0 | J24: =$C$11 -> 91
A25: F-QC-038. Date/Rev : 22.04.24/01 | H25: F-QC-038. Date/Rev : 22.04.24/01
B27: PT. TEKUN ASAS SUMBER MAKMUR | I27: PT. TEKUN ASAS SUMBER MAKMUR
A28: Customer name | B28: : | C28: =$C$2 -> PT. KAWAI INDONESIA | F28: Code : | H28: Customer name | I28: : | J28: =$C$2 -> PT. KAWAI INDONESIA | M28: Code :
A29: Part no | B29: : | C29: =$C$3 -> 955985 | F29: =$F$3 -> 226 | H29: Part no | I29: : | J29: =$C$3 -> 955985 | M29: =$F$3 -> 226
A30: Part name | B30: : | C30: =$C$4 -> DIN CONNECTOR FITTING | H30: Part name | I30: : | J30: =$C$4 -> DIN CONNECTOR FITTING
A31: Model | B31: : | C31: =$C$5 -> F28235 | H31: Model | I31: : | J31: =$C$5 -> F28235
A32: Delivery date | B32: : | F32: QR code | H32: Delivery date | I32: : | M32: QR code
A33: Berat per pack | B33: : | D33: Kg | H33: Berat per pack | I33: : | K33: Kg
A34: Quantity | B34: : | C34: =$C$8 -> 1000 | D34: Pcs | H34: Quantity | I34: : | J34: =$C$8 -> 1000 | K34: Pcs
A35: Inspector name | B35: : | H35: Inspector name | I35: :
A36: Prod. date | C36: Exp. date | E36: Status part | F36: OK | H36: Prod. date | J36: Exp. date | L36: Status part | M36: OK
A37: =$A$11 -> 0 | C37: =$C$11 -> 91 | H37: =$A$11 -> 0 | J37: =$C$11 -> 91
A38: F-QC-038. Date/Rev : 22.04.24/01 | H38: F-QC-038. Date/Rev : 22.04.24/01
B40: PT. TEKUN ASAS SUMBER MAKMUR | I40: PT. TEKUN ASAS SUMBER MAKMUR
A41: Customer name | B41: : | C41: =$C$2 -> PT. KAWAI INDONESIA | F41: Code : | H41: Customer name | I41: : | J41: =$C$2 -> PT. KAWAI INDONESIA | M41: Code :
A42: Part no | B42: : | C42: =$C$3 -> 955985 | F42: =$F$3 -> 226 | H42: Part no | I42: : | J42: =$C$3 -> 955985 | M42: =$F$3 -> 226
A43: Part name | B43: : | C43: =$C$4 -> DIN CONNECTOR FITTING | H43: Part name | I43: : | J43: =$C$4 -> DIN CONNECTOR FITTING
...

Sheet List Part
A1: LIST PART CUSTOMER
A3: Part Code | B3: Current Part No | C3: Part Description | D3: Customer | E3: Qty/Pack (Pcs) | F3: Prod. Date | G3: Exp. Date | H3: Model | I3: Delivery packaging | N3: Part No lama | O3: Qty sub pack | P3: Metode
I4: Berat Packaging (gram) | J4: Berat per pcs (gram) | K4: Berat total (Kg) | L4: Type Packaging | M4: Ukuran packaging (PxLxT)
A5: 001 | B5: VEN3500 | C5: KEY COVER ARM L PNT 001188 | D5: PT. YMMA | E5: 220 | G5: =F5+91 -> 91 | H5: - | I5: 280 | J5: 26.2 | K5: =(I5+(J5*E5))/1000 -> 6.044 | L5: Cartoon Box S2DW | M5: =VLOOKUP(L5,Packaging!$B$3:$C$21,2,0) -> 290 X 200 X 140 | O5: 5 | P5: Timbang
A6: 002 | B6: VEN3520 | C6: KEY COVER ARM L PNT 001190 | D6: PT. YMMA | E6: 220 | G6: =F6+91 -> 91 | H6: - | I6: 280 | J6: 38.6 | K6: =(I6+(J6*E6))/1000 -> 8.772 | L6: Cartoon Box S2DW | M6: =VLOOKUP(L6,Packaging!$B$3:$C$21,2,0) -> 290 X 200 X 140 | O6: 5 | P6: Timbang
A7: 003 | B7: VEN3510 | C7: KEY COVER ARM R PNT 001188 | D7: PT. YMMA | E7: 220 | G7: =F7+91 -> 91 | H7: - | I7: 280 | J7: 26.2 | K7: =(I7+(J7*E7))/1000 -> 6.044 | L7: Cartoon Box S2DW | M7: =VLOOKUP(L7,Packaging!$B$3:$C$21,2,0) -> 290 X 200 X 140 | O7: 5 | P7: Timbang
A8: 004 | B8: VEN3530 | C8: KEY COVER ARM R PNT 001190 | D8: PT. YMMA | E8: 220 | G8: =F8+91 -> 91 | H8: - | I8: 280 | J8: 38.6 | K8: =(I8+(J8*E8))/1000 -> 8.772 | L8: Cartoon Box S2DW | M8: =VLOOKUP(L8,Packaging!$B$3:$C$21,2,0) -> 290 X 200 X 140 | O8: 5 | P8: Timbang
A9: 005 | B9: VEW5100 | C9: FRONT RAIL PAINTED 000042 | D9: PT. YMMA | E9: 16 | G9: =F9+91 -> 91 | H9: - | I9: 948 | J9: 1650.4 | K9: =(I9+(J9*E9))/1000 -> 27.3544 | L9: Cartoon Box S25DW | M9: =VLOOKUP(L9,Packaging!$B$3:$C$21,2,0) -> 1410 X 165 X 175 | O9: 1 | P9: Timbang
A10: 006 | B10: VAX3500 | C10: SP GRILLE PAINTED 000418 | D10: PT. YMMA | E10: 40 | G10: =F10+91 -> 91 | H10: - | I10: 766 | J10: 170 | K10: =(I10+(J10*E10))/1000 -> 7.566 | L10: Cartoon Box S6DW | M10: =VLOOKUP(L10,Packaging!$B$3:$C$21,2,0) -> 390 X 350 X 280 | O10: 2 | P10: Timbang
A11: 007 | B11: VFV1400 | C11: DCIN ANGLE 001380 | D11: PT. YMMA | E11: 60 | G11: =F11+91 -> 91 | H11: - | I11: 280 | J11: 68.2 | K11: =(I11+(J11*E11))/1000 -> 4.372 | L11: Cartoon Box S2DW | M11: =VLOOKUP(L11,Packaging!$B$3:$C$21,2,0) -> 290 X 200 X 140 | O11: 5 | P11: Timbang
A12: 008 | B12: VEW4650 | C12: BOTTOM 7 PAINTED DE 000041 | D12: PT. YMMA | E12: 20 | G12: =F12+91 -> 91 | H12: - | J12: 5076.8 | K12: =(I12+(J12*E12))/1000 -> 101.536 | L12: TROLLY | M12: =VLOOKUP(L12,Packaging!$B$3:$C$21,2,0) -> 1000 X 880 X 1230 | O12: 1 | P12: Timbang
A13: 009 | B13: VDF9740 | C13: PEDAL PILLAR 000100 | D13: PT. YMMA | E13: 30 | G13: =F13+91 -> 91 | H13: - | I13: 430 | J13: 411 | K13: =(I13+(J13*E13))/1000 -> 12.76 | L13: Cartoon Box S18DW | M13: =VLOOKUP(L13,Packaging!$B$3:$C$21,2,0) -> 560 X 175 X 155 | O13: 1 | P13: Timbang
A14: 010 | B14: VHF3020 | C14: PEDAL PILLAR 000101 | D14: PT. YMMA | E14: 30 | G14: =F14+91 -> 91 | H14: - | I14: 430 | J14: 411 | K14: =(I14+(J14*E14))/1000 -> 12.76 | L14: Cartoon Box S18DW | M14: =VLOOKUP(L14,Packaging!$B$3:$C$21,2,0) -> 560 X 175 X 155 | N14: ZY71610 | O14: 1 | P14: Timbang
A15: 011 | B15: ZK72470 | C15: FOOT BASE BOARD 2 8K48/8N32 | D15: PT. YMMA | E15: 28 | G15: =F15+91 -> 91 | H15: - | I15: 378 | J15: 437.8 | K15: =(I15+(J15*E15))/1000 -> 12.6364 | L15: Cartoon Box S14DW | M15: =VLOOKUP(L15,Packaging!$B$3:$C$21,2,0) -> 400 X 240 X 130 | O15: 2 | P15: Timbang
A16: 012 | B16: VEY8740 | C16: BACK TOE L 001366 | D16: PT. YMMA | E16: 100 | G16: =F16+91 -> 91 | H16: - | I16: 280 | J16: 91 | K16: =(I16+(J16*E16))/1000 -> 9.38 | L16: Cartoon Box S2DW | M16: =VLOOKUP(L16,Packaging!$B$3:$C$21,2,0) -> 290 X 200 X 140 | O16: 5 | P16: Timbang
A17: 013 | B17: VEY8750 | C17: BACK TOE R 001366 | D17: PT. YMMA | E17: 100 | G17: =F17+91 -> 91 | H17: - | I17: 280 | J17: 91 | K17: =(I17+(J17*E17))/1000 -> 9.38 | L17: Cartoon Box S2DW | M17: =VLOOKUP(L17,Packaging!$B$3:$C$21,2,0) -> 290 X 200 X 140 | O17: 5 | P17: Timbang
A18: 014 | B18: VEN3810 | C18: T-BOARD GRILLE ASSY 001188 | D18: PT. YMMA | E18: 20 | G18: =F18+91 -> 91 | H18: - | I18: 580 | J18: 1034 | K18: =(I18+(J18*E18))/1000 -> 21.26 | L18: Cartoon Box S24DW | M18: =VLOOKUP(L18,Packaging!$B$3:$C$21,2,0) -> 1380 X 150 X 80 | O18: 1 | P18: Timbang
A19: 015 | B19: VEN3830 | C19: T-BOARD GRILLE ASSY 001190 | D19: PT. YMMA | E19: 20 | G19: =F19+91 -> 91 | H19: - | I19: 580 | J19: 1034 | K19: =(I19+(J19*E19))/1000 -> 21.26 | L19: Cartoon Box S24DW | M19: =VLOOKUP(L19,Packaging!$B$3:$C$21,2,0) -> 1380 X 150 X 80 | O19: 1 | P19: Timbang
A20: 016 | B20: VEW8810 | C20: AMP BOX PAINTED GP TA3 | D20: PT. YMMA | E20: 12 | G20: =F20+91 -> 91 | H20: - | I20: 766 | J20: 610 | K20: =(I20+(J20*E20))/1000 -> 8.086 | L20: Cartoon Box S6DW | M20: =VLOOKUP(L20,Packaging!$B$3:$C$21,2,0) -> 390 X 350 X 280 | O20: 1 | P20: Timbang
A21: 017 | B21: VGJ1470 | C21: BACK SP GRILLE 001798 | D21: PT. YMMA | E21: 40 | G21: =F21+91 -> 91 | H21: - | I21: 378 | J21: 724 | K21: =(I21+(J21*E21))/1000 -> 29.338 | L21: Cartoon Box S14DW | M21: =VLOOKUP(L21,Packaging!$B$3:$C$21,2,0) -> 400 X 240 X 130 | O21: 4 | P21: Timbang
A22: 018 | B22: VGJ2260 | C22: KEYCOVER ARM L 001798 | D22: PT. YMMA | E22: 360 | G22: =F22+91 -> 91 | H22: - | I22: 280 | J22: 26 | K22: =(I22+(J22*E22))/1000 -> 9.64 | L22: Cartoon Box S2DW | M22: =VLOOKUP(L22,Packaging!$B$3:$C$21,2,0) -> 290 X 200 X 140 | O22: 20 | P22: Timbang
A23: 019 | B23: VGJ2220 | C23: KEYCOVER ARM L PNT 001798 | D23: PT. YMMA | E23: 360 | G23: =F23+91 -> 91 | H23: - | I23: 280 | J23: 26.8 | K23: =(I23+(J23*E23))/1000 -> 9.928 | L23: Cartoon Box S2DW | M23: =VLOOKUP(L23,Packaging!$B$3:$C$21,2,0) -> 290 X 200 X 140 | O23: 5 | P23: Timbang
A24: 020 | B24: VGJ2270 | C24: KEYCOVER ARM R 001798 | D24: PT. YMMA | E24: 360 | G24: =F24+91 -> 91 | H24: - | I24: 280 | J24: 26 | K24: =(I24+(J24*E24))/1000 -> 9.64 | L24: Cartoon Box S2DW | M24: =VLOOKUP(L24,Packaging!$B$3:$C$21,2,0) -> 290 X 200 X 140 | O24: 20 | P24: Timbang
A25: 021 | B25: VGJ2230 | C25: KEYCOVER ARM R PNT 001798 | D25: PT. YMMA | E25: 360 | G25: =F25+91 -> 91 | H25: - | I25: 280 | J25: 26.8 | K25: =(I25+(J25*E25))/1000 -> 9.928 | L25: Cartoon Box S2DW | M25: =VLOOKUP(L25,Packaging!$B$3:$C$21,2,0) -> 290 X 200 X 140 | O25: 5 | P25: Timbang
A26: 022 | B26: VFA1570 | C26: T-BOARD GRILLE ASSY 001380 | D26: PT. YMMA | E26: 20 | G26: =F26+91 -> 91 | H26: - | I26: 1128 | J26: 1076 | K26: =(I26+(J26*E26))/1000 -> 22.648 | L26: NA | M26: =VLOOKUP(L26,Packaging!$B$3:$C$21,2,0) -> #N/A | O26: 1 | P26: Timbang
... A57: 053 | B57: VEW8840 | C57: AMP BRACKET UP TA3 TC3 | D57: PT. YMMA | E57: 20 | G57: =F57+91 -> 91 | H57: - | I57: 280 | J57: 419.2 | K57: =(I57+(J57*E57))/1000 -> 8.664 | L57: Cartoon Box S2DW | M57: =VLOOKUP(L57,Packaging!$B$3:$C$21,2,0) -> 290 X 200 X 140 | O57: 5 | P57: Timbang
A58: 054 | B58: VEW3720 | C58: BOTTOM 6 PAINTED DE 000040 | D58: PT. YMMA | E58: 20 | G58: =F58+91 -> 91 | H58: - | J58: 4152.4 | K58: =(I58+(J58*E58))/1000 -> 83.048 | L58: TROLLY | M58: =VLOOKUP(L58,Packaging!$B$3:$C$21,2,0) -> 1000 X 880 X 1230 | O58: 1 | P58: Timbang
A59: 055 | B59: VEW4000 | C59: PW COVER : | D59: PT. YMMA | E59: 32 | G59: =F59+91 -> 91 | H59: - | I59: 280 | J59: 110 | K59: =(I59+(J59*E59))/1000 -> 3.8 | L59: Cartoon Box S2DW | M59: =VLOOKUP(L59,Packaging!$B$3:$C$21,2,0) -> 290 X 200 X 140 | O59: 2 | P59: Timbang
A60: 056 | B60: VFG0380 | C60: BOTTOMCASE PAINTED SC3 TC3 BK | D60: PT. YMMA | E60: 9 | G60: =F60+91 -> 91 | H60: - | I60: 278 | J60: 332.2 | K60: =(I60+(J60*E60))/1000 -> 3.2678 | L60: Cartoon Box S1DW | M60: =VLOOKUP(L60,Packaging!$B$3:$C$21,2,0) -> 360 X 270 X 128 | O60: 1 | P60: Timbang
A61: 057 | B61: ZC05400 | C61: BACK TOP RAIL ANGLE 1.6 L : | D61: PT. YMMA | E61: 250 | G61: =F61+91 -> 91 | H61: - | I61: 280 | J61: 87.4 | K61: =(I61+(J61*E61))/1000 -> 22.13 | L61: Cartoon Box S2DW | M61: =VLOOKUP(L61,Packaging!$B$3:$C$21,2,0) -> 290 X 200 X 140 | O61: 50 | P61: Timbang
A62: 058 | B62: VFU1430 | C62: BOTTOMCASE H PAINTED BK 208EX EN55035 | D62: PT. YMMA | E62: 9 | G62: =F62+91 -> 91 | H62: - | I62: 278 | J62: 320 | K62: =(I62+(J62*E62))/1000 -> 3.158 | L62: Cartoon Box S1DW | M62: =VLOOKUP(L62,Packaging!$B$3:$C$21,2,0) -> 360 X 270 X 128 | N62: ZZ34950 | O62: 1 | P62: Timbang
A63: 059 | B63: VFJ2870 | C63: DC IN HOLDER 16V | D63: PT. YMMA | E63: 600 | G63: =F63+91 -> 91 | H63: - | I63: 280 | J63: 8.4 | K63: =(I63+(J63*E63))/1000 -> 5.32 | L63: Cartoon Box S2DW | M63: =VLOOKUP(L63,Packaging!$B$3:$C$21,2,0) -> 290 X 200 X 140 | O63: 150 | P63: Timbang
A64: 060 | B64: ZA88910 | C64: PAD ANGLE #3237 | D64: PT. YMMA | E64: 400 | G64: =F64+91 -> 91 | H64: - | I64: 278 | J64: 12.4 | K64: =(I64+(J64*E64))/1000 -> 5.238 | L64: Cartoon Box S1DW | M64: =VLOOKUP(L64,Packaging!$B$3:$C$21,2,0) -> 360 X 270 X 128 | O64: 50 | P64: Timbang
A65: 061 | B65: ZE26620 | C65: GRAND METAL HAJK 8I55 | D65: PT. YMMA | E65: 600 | G65: =F65+91 -> 91 | H65: - | I65: 280 | J65: 7.8 | K65: =(I65+(J65*E65))/1000 -> 4.96 | L65: Cartoon Box S2DW | M65: =VLOOKUP(L65,Packaging!$B$3:$C$21,2,0) -> 290 X 200 X 140 | O65: 150 | P65: Timbang
A66: 062 | B66: ZC33270 | C66: AC ADAPTOR COVER #3238 | D66: PT. YMMA | E66: 30 | G66: =F66+91 -> 91 | H66: - | I66: 278 | J66: 124.4 | K66: =(I66+(J66*E66))/1000 -> 4.01 | L66: Cartoon Box S1DW | M66: =VLOOKUP(L66,Packaging!$B$3:$C$21,2,0) -> 360 X 270 X 128 | O66: 1 | P66: Timbang
A67: 063 | B67: ZC11150 | C67: HOLDER #3238 | D67: PT. YMMA | E67: 1000 | G67: =F67+91 -> 91 | H67: - | I67: 280 | J67: 10 | K67: =(I67+(J67*E67))/1000 -> 10.28 | L67: Cartoon Box S2DW | M67: =VLOOKUP(L67,Packaging!$B$3:$C$21,2,0) -> 290 X 200 X 140 | O67: 10 | P67: Timbang
A68: 064 | B68: VEN3280 | C68: SIDE BOARD ANGLE L 001188 | D68: PT. YMMA | E68: 30 | G68: =F68+91 -> 91 | H68: - | I68: 430 | J68: 333.6 | K68: =(I68+(J68*E68))/1000 -> 10.438 | L68: Cartoon Box S18DW | M68: =VLOOKUP(L68,Packaging!$B$3:$C$21,2,0) -> 560 X 175 X 155 | O68: 5 | P68: Timbang
A69: 065 | B69: VEN3290 | C69: SIDE BOARD ANGLE R 001188 | D69: PT. YMMA | E69: 30 | G69: =F69+91 -> 91 | H69: - | I69: 430 | J69: 333.6 | K69: =(I69+(J69*E69))/1000 -> 10.438 | L69: Cartoon Box S18DW | M69: =VLOOKUP(L69,Packaging!$B$3:$C$21,2,0) -> 560 X 175 X 155 | O69: 5 | P69: Timbang
A70: 066 | B70: VEN4160 | C70: BACK SP GRILLE 001188 | D70: PT. YMMA | E70: 100 | G70: =F70+91 -> 91 | H70: - | I70: 278 | J70: 36 | K70: =(I70+(J70*E70))/1000 -> 3.878 | L70: Cartoon Box S1DW | M70: =VLOOKUP(L70,Packaging!$B$3:$C$21,2,0) -> 360 X 270 X 128 | O70: 4 | P70: Timbang
A71: 067 | B71: VEF9530 | C71: U FR BOARD SILL ANGLE 001191 | D71: PT. YMMA | E71: 20 | G71: =F71+91 -> 91 | H71: - | I71: 580 | J71: 952.4 | K71: =(I71+(J71*E71))/1000 -> 19.628 | L71: Cartoon Box S24DW | M71: =VLOOKUP(L71,Packaging!$B$3:$C$21,2,0) -> 1380 X 150 X 80 | O71: 20 | P71: Timbang
...

Sheet Packaging
A2: No | B2: Type Packaging | C2: Ukuran packaging (P x L x T) | D2: BERAT BOX
A3: 1 | B3: Cartoon Box S1DW | C3: 360 X 270 X 128 | D3: 278
A4: 2 | B4: Cartoon Box S2DW | C4: 290 X 200 X 140 | D4: 280
A5: 3 | B5: Cartoon Box S3DW | C5: 280 X 90 X 150 | D5: 134
A6: 4 | B6: Cartoon Box S4DW | C6: 230 X 90 X 180 | D6: 172
A7: 5 | B7: Cartoon Box S6DW | C7: 390 X 350 X 280 | D7: 766
A8: 6 | B8: Cartoon Box S7W | C8: 620 X 120 X 150 | D8: 157
A9: 7 | B9: Cartoon Box S14DW | C9: 400 X 240 X 130 | D9: 378
A10: 8 | B10: Cartoon Box S18DW | C10: 560 X 175 X 155 | D10: 430
A11: 9 | B11: Cartoon Box S20DW | C11: 485 X 356 X 289 | D11: 494
A12: 10 | B12: Cartoon Box S21DW | C12: 810 X 160 X180 | D12: 556
A13: 11 | B13: Cartoon Box S22DW | C13: 455 X 445 X 375 | D13: 1216
A14: 12 | B14: Cartoon Box S23DW | C14: 290 X 200 X 100 | D14: 244
... A17: 15 | B17: Cartoon Box S26DW | C17: 1200 X 190 X 250 | D17: 1040
A18: 16 | B18: TROLLY | C18: 1000 X 880 X 1230
A19: 17 | B19: Box SII | C19: 1460 X 200 X 160

Sheet clean_list_part
A1: LIST PART CUSTOMER
A4: Part Code | B4: Current Part No | C4: Part Description | D4: Customer | E4: Qty/Pack(Pcs) | F4: Prod. Date | G4: Exp. Date | H4: Model | I4: Berat Packaging (gram) | J4: Berat per pcs (gram) | K4: Berat total(Kg) | L4: Type Packaging | M4: Ukuran packaging (PxLxT) | N4: Part No lama | O4: Qty sub pack | P4: Metode
A5: 001 | B5: VEN3500 | C5: KEY COVER ARM L PNT 001188 | D5: PT. YMMA | E5: 220 | G5: =F5+91 -> 91 | H5: - | I5: 280 | J5: 26.2 | K5: =(I5+(J5*E5))/1000 -> 6.044 | L5: Cartoon Box S2DW | M5: =VLOOKUP(L5,Packaging!$B$3:$C$21,2,0) -> 290 X 200 X 140 | O5: 5 | P5: Timbang
A6: 002 | B6: VEN3520 | C6: KEY COVER ARM L PNT 001190 | D6: PT. YMMA | E6: 220 | G6: =F6+91 -> 91 | H6: - | I6: 280 | J6: 38.6 | K6: =(I6+(J6*E6))/1000 -> 8.772 | L6: Cartoon Box S2DW | M6: =VLOOKUP(L6,Packaging!$B$3:$C$21,2,0) -> 290 X 200 X 140 | O6: 5 | P6: Timbang
A7: 003 | B7: VEN3510 | C7: KEY COVER ARM R PNT 001188 | D7: PT. YMMA | E7: 220 | G7: =F7+91 -> 91 | H7: - | I7: 280 | J7: 26.2 | K7: =(I7+(J7*E7))/1000 -> 6.044 | L7: Cartoon Box S2DW | M7: =VLOOKUP(L7,Packaging!$B$3:$C$21,2,0) -> 290 X 200 X 140 | O7: 5 | P7: Timbang
A8: 004 | B8: VEN3530 | C8: KEY COVER ARM R PNT 001190 | D8: PT. YMMA | E8: 220 | G8: =F8+91 -> 91 | H8: - | I8: 280 | J8: 38.6 | K8: =(I8+(J8*E8))/1000 -> 8.772 | L8: Cartoon Box S2DW | M8: =VLOOKUP(L8,Packaging!$B$3:$C$21,2,0) -> 290 X 200 X 140 | O8: 5 | P8: Timbang
A9: 005 | B9: VEW5100 | C9: FRONT RAIL PAINTED 000042 | D9: PT. YMMA | E9: 16 | G9: =F9+91 -> 91 | H9: - | I9: 948 | J9: 1650.4 | K9: =(I9+(J9*E9))/1000 -> 27.3544 | L9: Cartoon Box S25DW | M9: =VLOOKUP(L9,Packaging!$B$3:$C$21,2,0) -> 1410 X 165 X 175 | O9: 1 | P9: Timbang
A10: 006 | B10: VAX3500 | C10: SP GRILLE PAINTED 000418 | D10: PT. YMMA | E10: 40 | G10: =F10+91 -> 91 | H10: - | I10: 766 | J10: 170 | K10: =(I10+(J10*E10))/1000 -> 7.566 | L10: Cartoon Box S6DW | M10: =VLOOKUP(L10,Packaging!$B$3:$C$21,2,0) -> 390 X 350 X 280 | O10: 2 | P10: Timbang
A11: 007 | B11: VFV1400 | C11: DCIN ANGLE 001380 | D11: PT. YMMA | E11: 60 | G11: =F11+91 -> 91 | H11: - | I11: 280 | J11: 68.2 | K11: =(I11+(J11*E11))/1000 -> 4.372 | L11: Cartoon Box S2DW | M11: =VLOOKUP(L11,Packaging!$B$3:$C$21,2,0) -> 290 X 200 X 140 | O11: 5 | P11: Timbang
A12: 008 | B12: VEW4650 | C12: BOTTOM 7 PAINTED DE 000041 | D12: PT. YMMA | E12: 20 | G12: =F12+91 -> 91 | H12: - | J12: 5076.8 | K12: =(I12+(J12*E12))/1000 -> 101.536 | L12: TROLLY | M12: =VLOOKUP(L12,Packaging!$B$3:$C$21,2,0) -> 1000 X 880 X 1230 | O12: 1 | P12: Timbang
A13: 009 | B13: VDF9740 | C13: PEDAL PILLAR 000100 | D13: PT. YMMA | E13: 30 | G13: =F13+91 -> 91 | H13: - | I13: 430 | J13: 411 | K13: =(I13+(J13*E13))/1000 -> 12.76 | L13: Cartoon Box S18DW | M13: =VLOOKUP(L13,Packaging!$B$3:$C$21,2,0) -> 560 X 175 X 155 | O13: 1 | P13: Timbang
A14: 010 | B14: VHF3020 | C14: PEDAL PILLAR 000101 | D14: PT. YMMA | E14: 30 | G14: =F14+91 -> 91 | H14: - | I14: 430 | J14: 411 | K14: =(I14+(J14*E14))/1000 -> 12.76 | L14: Cartoon Box S18DW | M14: =VLOOKUP(L14,Packaging!$B$3:$C$21,2,0) -> 560 X 175 X 155 | N14: ZY71610 | O14: 1 | P14: Timbang
A15: 011 | B15: ZK72470 | C15: FOOT BASE BOARD 2 8K48/8N32 | D15: PT. YMMA | E15: 28 | G15: =F15+91 -> 91 | H15: - | I15: 378 | J15: 437.8 | K15: =(I15+(J15*E15))/1000 -> 12.6364 | L15: Cartoon Box S14DW | M15: =VLOOKUP(L15,Packaging!$B$3:$C$21,2,0) -> 400 X 240 X 130 | O15: 2 | P15: Timbang
A16: 012 | B16: VEY8740 | C16: BACK TOE L 001366 | D16: PT. YMMA | E16: 100 | G16: =F16+91 -> 91 | H16: - | I16: 280 | J16: 91 | K16: =(I16+(J16*E16))/1000 -> 9.38 | L16: Cartoon Box S2DW | M16: =VLOOKUP(L16,Packaging!$B$3:$C$21,2,0) -> 290 X 200 X 140 | O16: 5 | P16: Timbang
A17: 013 | B17: VEY8750 | C17: BACK TOE R 001366 | D17: PT. YMMA | E17: 100 | G17: =F17+91 -> 91 | H17: - | I17: 280 | J17: 91 | K17: =(I17+(J17*E17))/1000 -> 9.38 | L17: Cartoon Box S2DW | M17: =VLOOKUP(L17,Packaging!$B$3:$C$21,2,0) -> 290 X 200 X 140 | O17: 5 | P17: Timbang
A18: 014 | B18: VEN3810 | C18: T-BOARD GRILLE ASSY 001188 | D18: PT. YMMA | E18: 20 | G18: =F18+91 -> 91 | H18: - | I18: 580 | J18: 1034 | K18: =(I18+(J18*E18))/1000 -> 21.26 | L18: Cartoon Box S24DW | M18: =VLOOKUP(L18,Packaging!$B$3:$C$21,2,0) -> 1380 X 150 X 80 | O18: 1 | P18: Timbang
A19: 015 | B19: VEN3830 | C19: T-BOARD GRILLE ASSY 001190 | D19: PT. YMMA | E19: 20 | G19: =F19+91 -> 91 | H19: - | I19: 580 | J19: 1034 | K19: =(I19+(J19*E19))/1000 -> 21.26 | L19: Cartoon Box S24DW | M19: =VLOOKUP(L19,Packaging!$B$3:$C$21,2,0) -> 1380 X 150 X 80 | O19: 1 | P19: Timbang
A20: 016 | B20: VEW8810 | C20: AMP BOX PAINTED GP TA3 | D20: PT. YMMA | E20: 12 | G20: =F20+91 -> 91 | H20: - | I20: 766 | J20: 610 | K20: =(I20+(J20*E20))/1000 -> 8.086 | L20: Cartoon Box S6DW | M20: =VLOOKUP(L20,Packaging!$B$3:$C$21,2,0) -> 390 X 350 X 280 | O20: 1 | P20: Timbang
A21: 017 | B21: VGJ1470 | C21: BACK SP GRILLE 001798 | D21: PT. YMMA | E21: 40 | G21: =F21+91 -> 91 | H21: - | I21: 378 | J21: 724 | K21: =(I21+(J21*E21))/1000 -> 29.338 | L21: Cartoon Box S14DW | M21: =VLOOKUP(L21,Packaging!$B$3:$C$21,2,0) -> 400 X 240 X 130 | O21: 4 | P21: Timbang
A22: 018 | B22: VGJ2260 | C22: KEYCOVER ARM L 001798 | D22: PT. YMMA | E22: 360 | G22: =F22+91 -> 91 | H22: - | I22: 280 | J22: 26 | K22: =(I22+(J22*E22))/1000 -> 9.64 | L22: Cartoon Box S2DW | M22: =VLOOKUP(L22,Packaging!$B$3:$C$21,2,0) -> 290 X 200 X 140 | O22: 20 | P22: Timbang
A23: 019 | B23: VGJ2220 | C23: KEYCOVER ARM L PNT 001798 | D23: PT. YMMA | E23: 360 | G23: =F23+91 -> 91 | H23: - | I23: 280 | J23: 26.8 | K23: =(I23+(J23*E23))/1000 -> 9.928 | L23: Cartoon Box S2DW | M23: =VLOOKUP(L23,Packaging!$B$3:$C$21,2,0) -> 290 X 200 X 140 | O23: 5 | P23: Timbang
A24: 020 | B24: VGJ2270 | C24: KEYCOVER ARM R 001798 | D24: PT. YMMA | E24: 360 | G24: =F24+91 -> 91 | H24: - | I24: 280 | J24: 26 | K24: =(I24+(J24*E24))/1000 -> 9.64 | L24: Cartoon Box S2DW | M24: =VLOOKUP(L24,Packaging!$B$3:$C$21,2,0) -> 290 X 200 X 140 | O24: 20 | P24: Timbang
A25: 021 | B25: VGJ2230 | C25: KEYCOVER ARM R PNT 001798 | D25: PT. YMMA | E25: 360 | G25: =F25+91 -> 91 | H25: - | I25: 280 | J25: 26.8 | K25: =(I25+(J25*E25))/1000 -> 9.928 | L25: Cartoon Box S2DW | M25: =VLOOKUP(L25,Packaging!$B$3:$C$21,2,0) -> 290 X 200 X 140 | O25: 5 | P25: Timbang
A26: 022 | B26: VFA1570 | C26: T-BOARD GRILLE ASSY 001380 | D26: PT. YMMA | E26: 20 | G26: =F26+91 -> 91 | H26: - | I26: 1128 | J26: 1076 | K26: =(I26+(J26*E26))/1000 -> 22.648 | L26: NA | M26: =VLOOKUP(L26,Packaging!$B$3:$C$21,2,0) -> #N/A | O26: 1 | P26: Timbang
... A57: 053 | B57: VEW8840 | C57: AMP BRACKET UP TA3 TC3 | D57: PT. YMMA | E57: 20 | G57: =F57+91 -> 91 | H57: - | I57: 280 | J57: 419.2 | K57: =(I57+(J57*E57))/1000 -> 8.664 | L57: Cartoon Box S2DW | M57: =VLOOKUP(L57,Packaging!$B$3:$C$21,2,0) -> 290 X 200 X 140 | O57: 5 | P57: Timbang
A58: 054 | B58: VEW3720 | C58: BOTTOM 6 PAINTED DE 000040 | D58: PT. YMMA | E58: 20 | G58: =F58+91 -> 91 | H58: - | J58: 4152.4 | K58: =(I58+(J58*E58))/1000 -> 83.048 | L58: TROLLY | M58: =VLOOKUP(L58,Packaging!$B$3:$C$21,2,0) -> 1000 X 880 X 1230 | O58: 1 | P58: Timbang
A59: 055 | B59: VEW4000 | C59: PW COVER : | D59: PT. YMMA | E59: 32 | G59: =F59+91 -> 91 | H59: - | I59: 280 | J59: 110 | K59: =(I59+(J59*E59))/1000 -> 3.8 | L59: Cartoon Box S2DW | M59: =VLOOKUP(L59,Packaging!$B$3:$C$21,2,0) -> 290 X 200 X 140 | O59: 2 | P59: Timbang
A60: 056 | B60: VFG0380 | C60: BOTTOMCASE PAINTED SC3 TC3 BK | D60: PT. YMMA | E60: 9 | G60: =F60+91 -> 91 | H60: - | I60: 278 | J60: 332.2 | K60: =(I60+(J60*E60))/1000 -> 3.2678 | L60: Cartoon Box S1DW | M60: =VLOOKUP(L60,Packaging!$B$3:$C$21,2,0) -> 360 X 270 X 128 | O60: 1 | P60: Timbang
A61: 057 | B61: ZC05400 | C61: BACK TOP RAIL ANGLE 1.6 L : | D61: PT. YMMA | E61: 250 | G61: =F61+91 -> 91 | H61: - | I61: 280 | J61: 87.4 | K61: =(I61+(J61*E61))/1000 -> 22.13 | L61: Cartoon Box S2DW | M61: =VLOOKUP(L61,Packaging!$B$3:$C$21,2,0) -> 290 X 200 X 140 | O61: 50 | P61: Timbang
A62: 058 | B62: VFU1430 | C62: BOTTOMCASE H PAINTED BK 208EX EN55035 | D62: PT. YMMA | E62: 9 | G62: =F62+91 -> 91 | H62: - | I62: 278 | J62: 320 | K62: =(I62+(J62*E62))/1000 -> 3.158 | L62: Cartoon Box S1DW | M62: =VLOOKUP(L62,Packaging!$B$3:$C$21,2,0) -> 360 X 270 X 128 | N62: ZZ34950 | O62: 1 | P62: Timbang
A63: 059 | B63: VFJ2870 | C63: DC IN HOLDER 16V | D63: PT. YMMA | E63: 600 | G63: =F63+91 -> 91 | H63: - | I63: 280 | J63: 8.4 | K63: =(I63+(J63*E63))/1000 -> 5.32 | L63: Cartoon Box S2DW | M63: =VLOOKUP(L63,Packaging!$B$3:$C$21,2,0) -> 290 X 200 X 140 | O63: 150 | P63: Timbang
A64: 060 | B64: ZA88910 | C64: PAD ANGLE #3237 | D64: PT. YMMA | E64: 400 | G64: =F64+91 -> 91 | H64: - | I64: 278 | J64: 12.4 | K64: =(I64+(J64*E64))/1000 -> 5.238 | L64: Cartoon Box S1DW | M64: =VLOOKUP(L64,Packaging!$B$3:$C$21,2,0) -> 360 X 270 X 128 | O64: 50 | P64: Timbang
A65: 061 | B65: ZE26620 | C65: GRAND METAL HAJK 8I55 | D65: PT. YMMA | E65: 600 | G65: =F65+91 -> 91 | H65: - | I65: 280 | J65: 7.8 | K65: =(I65+(J65*E65))/1000 -> 4.96 | L65: Cartoon Box S2DW | M65: =VLOOKUP(L65,Packaging!$B$3:$C$21,2,0) -> 290 X 200 X 140 | O65: 150 | P65: Timbang
A66: 062 | B66: ZC33270 | C66: AC ADAPTOR COVER #3238 | D66: PT. YMMA | E66: 30 | G66: =F66+91 -> 91 | H66: - | I66: 278 | J66: 124.4 | K66: =(I66+(J66*E66))/1000 -> 4.01 | L66: Cartoon Box S1DW | M66: =VLOOKUP(L66,Packaging!$B$3:$C$21,2,0) -> 360 X 270 X 128 | O66: 1 | P66: Timbang
A67: 063 | B67: ZC11150 | C67: HOLDER #3238 | D67: PT. YMMA | E67: 1000 | G67: =F67+91 -> 91 | H67: - | I67: 280 | J67: 10 | K67: =(I67+(J67*E67))/1000 -> 10.28 | L67: Cartoon Box S2DW | M67: =VLOOKUP(L67,Packaging!$B$3:$C$21,2,0) -> 290 X 200 X 140 | O67: 10 | P67: Timbang
A68: 064 | B68: VEN3280 | C68: SIDE BOARD ANGLE L 001188 | D68: PT. YMMA | E68: 30 | G68: =F68+91 -> 91 | H68: - | I68: 430 | J68: 333.6 | K68: =(I68+(J68*E68))/1000 -> 10.438 | L68: Cartoon Box S18DW | M68: =VLOOKUP(L68,Packaging!$B$3:$C$21,2,0) -> 560 X 175 X 155 | O68: 5 | P68: Timbang
A69: 065 | B69: VEN3290 | C69: SIDE BOARD ANGLE R 001188 | D69: PT. YMMA | E69: 30 | G69: =F69+91 -> 91 | H69: - | I69: 430 | J69: 333.6 | K69: =(I69+(J69*E69))/1000 -> 10.438 | L69: Cartoon Box S18DW | M69: =VLOOKUP(L69,Packaging!$B$3:$C$21,2,0) -> 560 X 175 X 155 | O69: 5 | P69: Timbang
A70: 066 | B70: VEN4160 | C70: BACK SP GRILLE 001188 | D70: PT. YMMA | E70: 100 | G70: =F70+91 -> 91 | H70: - | I70: 278 | J70: 36 | K70: =(I70+(J70*E70))/1000 -> 3.878 | L70: Cartoon Box S1DW | M70: =VLOOKUP(L70,Packaging!$B$3:$C$21,2,0) -> 360 X 270 X 128 | O70: 4 | P70: Timbang
A71: 067 | B71: VEF9530 | C71: U FR BOARD SILL ANGLE 001191 | D71: PT. YMMA | E71: 20 | G71: =F71+91 -> 91 | H71: - | I71: 580 | J71: 952.4 | K71: =(I71+(J71*E71))/1000 -> 19.628 | L71: Cartoon Box S24DW | M71: =VLOOKUP(L71,Packaging!$B$3:$C$21,2,0) -> 1380 X 150 X 80 | O71: 20 | P71: Timbang
A72: 068 | B72: ZX76300 | C72: DM SUPPORT ANGLE 1.0 : : | D72: PT. YMMA | E72: 1000 | G72: =F72+91 -> 91 | H72: - | I72: 280 | J72: 1.6 | K72: =(I72+(J72*E72))/1000 -> 1.88 | L72: Cartoon Box S2DW | M72: =VLOOKUP(L72,Packaging!$B$3:$C$21,2,0) -> 290 X 200 X 140 | O72: 250 | P72: Timbang
...
